<?xml version="1.0" encoding="UTF-8"?><testrun duration="15" footerText="Generated by PyCharm on 26/07/17 5:24 PM" name="Unittests in TestIo">
    <count name="total" value="5"/>
    <count name="failed" value="4"/>
    <count name="passed" value="1"/>
    <config nameIsGenerated="true" configId="tests" name="Unittests in TestIo">
        <option name="INTERPRETER_OPTIONS" value=""/>
        <option name="PARENT_ENVS" value="true"/>
        <envs/>
        <option name="SDK_HOME" value=""/>
        <option name="WORKING_DIRECTORY" value="C:/Users/User/Documents/Personal_Projects/side-projects/GraphGenerator/graph-gen/test"/>
        <option name="IS_MODULE_SDK" value="true"/>
        <option name="ADD_CONTENT_ROOTS" value="true"/>
        <option name="ADD_SOURCE_ROOTS" value="true"/>
        <module name="graph-gen"/>
        <EXTENSION ID="PythonCoverageRunConfigurationExtension" enabled="false" sample_coverage="true" runner="coverage.py"/>
        <option name="SCRIPT_NAME" value="C:\Users\User\Documents\Personal_Projects\side-projects\GraphGenerator\graph-gen\test\TestIO.py"/>
        <option name="CLASS_NAME" value="TestIo"/>
        <option name="METHOD_NAME" value=""/>
        <option name="FOLDER_NAME" value=""/>
        <option name="TEST_TYPE" value="TEST_CLASS"/>
        <option name="PATTERN" value=""/>
        <option name="USE_PATTERN" value="false"/>
        <option name="PUREUNITTEST" value="true"/>
        <option name="PARAMS" value=""/>
        <option name="USE_PARAM" value="false"/>
    </config>
    <suite duration="15" locationUrl="python_uttestid:///test.TestIO.TestIo" name="test.TestIO.TestIo" status="failed">
        <test duration="0" locationUrl="python_uttestid:///test.TestIO.TestIo.test_arrow_case" name="test_arrow_case" status="failed">
            <output type="stderr">Failure
Traceback (most recent call last):
  File &amp;quot;C:\Users\User\Documents\Personal_Projects\side-projects\GraphGenerator\graph-gen\test\TestIO.py&amp;quot;, line 15, in test_arrow_case
    create_vertex_list(test_stream)
AssertionError: OSError not raised
</output>
        </test>
        <test duration="0" locationUrl="python_uttestid:///test.TestIO.TestIo.test_correct_input" name="test_correct_input" status="passed"/>
        <test duration="0" locationUrl="python_uttestid:///test.TestIO.TestIo.test_extra_data" name="test_extra_data" status="failed">
            <output type="stderr">Failure
Traceback (most recent call last):
  File &amp;quot;C:\Users\User\Documents\Personal_Projects\side-projects\GraphGenerator\graph-gen\test\TestIO.py&amp;quot;, line 39, in test_extra_data
    create_vertex_list(test_stream)
AssertionError: OSError not raised
</output>
        </test>
        <test duration="0" locationUrl="python_uttestid:///test.TestIO.TestIo.test_no_data" name="test_no_data" status="failed">
            <output type="stderr">Failure
Traceback (most recent call last):
  File &amp;quot;C:\Users\User\Documents\Personal_Projects\side-projects\GraphGenerator\graph-gen\test\TestIO.py&amp;quot;, line 28, in test_no_data
    create_vertex_list(test_stream)
AssertionError: OSError not raised
</output>
        </test>
        <test duration="15" locationUrl="python_uttestid:///test.TestIO.TestIo.test_non_number" name="test_non_number" status="failed">
            <output type="stderr">Failure
Traceback (most recent call last):
  File &amp;quot;C:\Users\User\Documents\Personal_Projects\side-projects\GraphGenerator\graph-gen\test\TestIO.py&amp;quot;, line 49, in test_non_number
    create_vertex_list(test_stream)
AssertionError: OSError not raised
</output>
        </test>
    </suite>
</testrun>
